# flask._compat

> Auto-generated documentation for [env.Lib.site-packages.flask._compat](..\..\..\..\..\env\Lib\site-packages\flask\_compat.py) module.

Some py2/py3 compatibility support based on a stripped down
version of six so we don't have to depend on a specific version
of it.

- [Smart-house-rest-api](..\..\..\..\README.md#description) / [Modules](..\..\..\..\MODULES.md#smart-house-rest-api-modules) / `Env` / `Lib` / `Site-packages` / [flask](index.md#flask) / flask._compat
    - [fspath](#fspath)
    - [implements_to_string](#implements_to_string)
    - [reraise](#reraise)
    - [with_metaclass](#with_metaclass)

:copyright: 2010 Pallets
:license: BSD-3-Clause

#### Attributes

- `BROKEN_PYPY_CTXMGR_EXIT` - Certain versions of pypy have a bug where clearing the exception stack
  breaks the __exit__ function in a very peculiar way.  The second level of
  exception blocks is necessary because pypy seems to forget to check if an
  exception happened until the next bytecode instruction?
  
  Relevant PyPy bugfix commit:
  https://bitbucket.org/pypy/pypy/commits/77ecf91c635a287e88e60d8ddb0f4e9df4003301
  According to ronan on #pypy IRC, it is released in PyPy2 2.3 and later
  versions.
  
  Ubuntu 14.04 has PyPy 2.2.1, which does exhibit this bug.: `False`

## fspath

[[find in source code]](..\..\..\..\..\env\Lib\site-packages\flask\_compat.py#L114)

```python
def fspath(path):
```

## implements_to_string

[[find in source code]](..\..\..\..\..\env\Lib\site-packages\flask\_compat.py#L54)

```python
def implements_to_string(cls):
```

## reraise

[[find in source code]](..\..\..\..\..\env\Lib\site-packages\flask\_compat.py#L36)

```python
def reraise(tp, value, tb=None):
```

## with_metaclass

[[find in source code]](..\..\..\..\..\env\Lib\site-packages\flask\_compat.py#L60)

```python
def with_metaclass(meta, *bases):
```

Create a base class with a metaclass.
